Workbook

Sheet 0. Datos Empresa
A1: Datos de la Empresa Analizada
A2: Este libro evalúa SIEMPRE una sola empresa. Todos los procesos que registre en las pestañas siguientes (0..N) deben pertenecer a esta misma empresa; si su equipo necesita analizar otra empresa, use una copia nueva de este libro.
A4: Nombre de la empresa | B4: UNIVERSIDAD EAFIT
A5: Sector / industria | B5: EDUCACIÓN
A6: Tamaño (No. empleados) | B6: 2800 APR
A7: Ciudad | B7: MEDELLIN
A8: Contacto en la empresa | B8: www.eafit.edu.co
A9: Cargo del contacto | B9: Dirección TI
A10: Equipo (integrantes) | B10: 5
A11: Fecha de evaluación | B11: 46310

Sheet 1. Catálogo Procesos
A1: Catálogo de procesos de: | B1: ='0. Datos Empresa'!$B$4 -> UNIVERSIDAD EAFIT
A3: Categoría (nivel 1) | B3: Proceso genérico (nivel 2) | C3: Aplica a esta empresa? | D3: Nombre específico en la empresa | E3: Dueño del proceso
A4: 1.0 Estrategia y Direccionamiento | B4: Definir y desplegar la estrategia organizacional
A5: 1.0 Estrategia y Direccionamiento | B5: Gestionar el portafolio de iniciativas/proyectos
A6: 2.0 Desarrollo de Producto/Servicio | B6: Diseñar y desarrollar nuevos productos o servicios
A7: 2.0 Desarrollo de Producto/Servicio | B7: Gestionar el ciclo de vida del producto/servicio
A8: 3.0 Mercadeo y Ventas | B8: Gestionar mercadeo y generación de demanda
A9: 3.0 Mercadeo y Ventas | B9: Gestionar el proceso comercial / ventas
A10: 3.0 Mercadeo y Ventas | B10: Gestionar precios y cotizaciones
A11: 4.0 Operaciones / Entrega | B11: Planificar y programar la operación
A12: 4.0 Operaciones / Entrega | B12: Producir o prestar el servicio
A13: 4.0 Operaciones / Entrega | B13: Gestionar la cadena de abastecimiento y logística
A14: 4.0 Operaciones / Entrega | B14: Gestionar inventarios y almacenamiento
A15: 5.0 Servicio al Cliente | B15: Gestionar solicitudes, quejas y reclamos (PQR)
... A20: 6.0 Gestión Humana | B20: Gestionar desempeño y desarrollo
A21: 7.0 Tecnología de la Información | B21: Administrar aplicaciones y sistemas | C21: Sí | D21: Administración de aplicaciones y plataformas de gestión TI | E21: Dirección de TI
A22: 7.0 Tecnología de la Información | B22: Gestionar infraestructura y soporte TI | C22: Sí | D22: Gestión de infraestructura de red, Wi-Fi, switches y puntos de acceso | E22: Infraestructura TI - Redes
A23: 7.0 Tecnología de la Información | B23: Gestionar seguridad de la información | C23: Sí | D23: Gestión de seguridad de la información y controles de acceso a la red | E23: Seguridad de la Información
A24: 8.0 Finanzas y Contabilidad | B24: Gestionar cuentas por cobrar y facturación
A25: 8.0 Finanzas y Contabilidad | B25: Gestionar cuentas por pagar y tesorería
A26: 8.0 Finanzas y Contabilidad | B26: Gestionar contabilidad y reportes financieros
A27: 8.0 Finanzas y Contabilidad | B27: Gestionar presupuesto y control de costos
A28: 9.0 Activos e Infraestructura Física | B28: Adquirir y gestionar activos fijos
A29: 9.0 Activos e Infraestructura Física | B29: Gestionar mantenimiento de instalaciones/equipos | C29: Sí | D29: Mantenimiento preventivo y correctivo de infraestructura tecnológica | E29: Infraestructura TI
A30: 10.0 Riesgo, Cumplimiento y Legal | B30: Gestionar riesgos corporativos
A31: 10.0 Riesgo, Cumplimiento y Legal | B31: Gestionar cumplimiento normativo y legal
A32: 11.0 Relacionamiento Externo | B32: Gestionar relacionamiento con proveedores | C32: Sí | D32: Gestión de proveedores de conectividad y tecnología | E32: Dirección de TI / Compras
A33: 11.0 Relacionamiento Externo | B33: Gestionar relacionamiento institucional / regulatorio
A34: 12.0 Datos y Analítica | B34: Gestionar gobierno y calidad de datos | C34: Sí | D34: Gobierno y calidad de inventario y datos de infraestructura TI | E34: Infraestructura TI - Redes
A35: 12.0 Datos y Analítica | B35: Generar reportes e inteligencia de negocio | C35: Sí | D35: Generación de reportes de disponibilidad, incidentes y desempeño de red | E35: Infraestructura TI - Redes
A37: Catálogo genérico basado en una taxonomía tipo APQC Process Classification Framework. Marque 'Sí' en los procesos que aplican a la empresa analizada (siempre la misma, definida en la pestaña '0. Datos Empresa'); agregue filas si la empresa tiene procesos propios que no aparecen aquí.

Sheet 2. Priorización Automatización
A1: Procesos evaluados de: | B1: ='0. Datos Empresa'!$B$4 -> UNIVERSIDAD EAFIT
A2: Proceso | C2: Preguntas de viabilidad (Q1-Q9) - responda Sí/No | L2: Resultado | N2: Datos operativos (tiempo, personas, costo)
A3: ID Proceso | B3: Nombre del Proceso | C3: Q1 | D3: Q2 | E3: Q3 | F3: Q4 | G3: Q5 | H3: Q6 | I3: Q7 | J3: Q8 | K3: Q9 | L3: Puntaje Viabilidad | M3: Clasificación | N3: Min./transacción | O3: Transacciones/mes | P3: Horas totales/mes | Q3: Personas involucradas | R3: Costo externo ($/mes)
A4: P01 | B4: Monitoreo de disponibilidad y alertas de switches y puntos de acceso | C4: Sí | D4: Sí | E4: Sí | F4: Sí | G4: Sí | H4: Sí | I4: Sí | J4: Sí | K4: Sí | L4: =IF(COUNTA(C4:K4)=0,"",COUNTIF(C4:K4,"Sí")/9) -> 1 | M4: =IF(L4="","",IF(L4>=0.86,"Totalmente automatizable",IF(L4>=0.71,"Automatizable","Descartar"))) -> Totalmente automatizable | N4: 5 | O4: 720 | P4: =IF(OR(N4="",O4=""),"",N4*O4/60) -> 60 | Q4: 3 | R4: 0
A5: P02 | B5: Generación periódica de reportes de desempeño de red | C5: Sí | D5: Sí | E5: Sí | F5: Sí | G5: Sí | H5: Sí | I5: Sí | J5: Sí | K5: Sí | L5: =IF(COUNTA(C5:K5)=0,"",COUNTIF(C5:K5,"Sí")/9) -> 1 | M5: =IF(L5="","",IF(L5>=0.86,"Totalmente automatizable",IF(L5>=0.71,"Automatizable","Descartar"))) -> Totalmente automatizable | N5: 20 | O5: 120 | P5: =IF(OR(N5="",O5=""),"",N5*O5/60) -> 40 | Q5: 2 | R5: 0
A6: P03 | B6: Registro, clasificación y seguimiento de incidentes de conectividad | C6: Sí | D6: Sí | E6: Sí | F6: Sí | G6: Sí | H6: Sí | I6: Sí | J6: Sí | K6: No | L6: =IF(COUNTA(C6:K6)=0,"",COUNTIF(C6:K6,"Sí")/9) -> 0.88888889 | M6: =IF(L6="","",IF(L6>=0.86,"Totalmente automatizable",IF(L6>=0.71,"Automatizable","Descartar"))) -> Totalmente automatizable | N6: 12 | O6: 180 | P6: =IF(OR(N6="",O6=""),"",N6*O6/60) -> 36 | Q6: 4 | R6: 0
A7: P04 | B7: Inventario y actualización de información de switches y AP | C7: Sí | D7: Sí | E7: Sí | F7: Sí | G7: Sí | H7: No | I7: Sí | J7: Sí | K7: Sí | L7: =IF(COUNTA(C7:K7)=0,"",COUNTIF(C7:K7,"Sí")/9) -> 0.88888889 | M7: =IF(L7="","",IF(L7>=0.86,"Totalmente automatizable",IF(L7>=0.71,"Automatizable","Descartar"))) -> Totalmente automatizable | N7: 8 | O7: 100 | P7: =IF(OR(N7="",O7=""),"",N7*O7/60) -> 13.333333 | Q7: 2 | R7: 0
A8: P05 | B8: Revisión y consolidación de logs de infraestructura | C8: Sí | D8: Sí | E8: Sí | F8: Sí | G8: Sí | H8: Sí | I8: Sí | J8: Sí | K8: Sí | L8: =IF(COUNTA(C8:K8)=0,"",COUNTIF(C8:K8,"Sí")/9) -> 1 | M8: =IF(L8="","",IF(L8>=0.86,"Totalmente automatizable",IF(L8>=0.71,"Automatizable","Descartar"))) -> Totalmente automatizable | N8: 10 | O8: 120 | P8: =IF(OR(N8="",O8=""),"",N8*O8/60) -> 20 | Q8: 2 | R8: 0
A9: P06 | B9: Programación y seguimiento de actualizaciones de firmware | C9: Sí | D9: Sí | E9: Sí | F9: Sí | G9: Sí | H9: Sí | I9: No | J9: Sí | K9: No | L9: =IF(COUNTA(C9:K9)=0,"",COUNTIF(C9:K9,"Sí")/9) -> 0.77777778 | M9: =IF(L9="","",IF(L9>=0.86,"Totalmente automatizable",IF(L9>=0.71,"Automatizable","Descartar"))) -> Automatizable | N9: 30 | O9: 12 | P9: =IF(OR(N9="",O9=""),"",N9*O9/60) -> 6 | Q9: 2 | R9: 0
A10: P07 | B10: Gestión de solicitudes de habilitación de puntos de red y VLAN | C10: Sí | D10: Sí | E10: Sí | F10: Sí | G10: Sí | H10: Sí | I10: Sí | J10: Sí | K10: No | L10: =IF(COUNTA(C10:K10)=0,"",COUNTIF(C10:K10,"Sí")/9) -> 0.88888889 | M10: =IF(L10="","",IF(L10>=0.86,"Totalmente automatizable",IF(L10>=0.71,"Automatizable","Descartar"))) -> Totalmente automatizable | N10: 15 | O10: 80 | P10: =IF(OR(N10="",O10=""),"",N10*O10/60) -> 20 | Q10: 3 | R10: 0
A11: P08 | B11: Seguimiento de ocupación estimada de aulas mediante sensores ESP32 | C11: Sí | D11: Sí | E11: Sí | F11: Sí | G11: Sí | H11: Sí | I11: Sí | J11: Sí | K11: Sí | L11: =IF(COUNTA(C11:K11)=0,"",COUNTIF(C11:K11,"Sí")/9) -> 1 | M11: =IF(L11="","",IF(L11>=0.86,"Totalmente automatizable",IF(L11>=0.71,"Automatizable","Descartar"))) -> Totalmente automatizable | N11: 3 | O11: 900 | P11: =IF(OR(N11="",O11=""),"",N11*O11/60) -> 45 | Q11: 1 | R11: 0
A12: P09 | L12: =IF(COUNTA(C12:K12)=0,"",COUNTIF(C12:K12,"Sí")/9) | M12: =IF(L12="","",IF(L12>=0.86,"Totalmente automatizable",IF(L12>=0.71,"Automatizable","Descartar"))) | P12: =IF(OR(N12="",O12=""),"",N12*O12/60)
A13: P10 | L13: =IF(COUNTA(C13:K13)=0,"",COUNTIF(C13:K13,"Sí")/9) | M13: =IF(L13="","",IF(L13>=0.86,"Totalmente automatizable",IF(L13>=0.71,"Automatizable","Descartar"))) | P13: =IF(OR(N13="",O13=""),"",N13*O13/60)
A14: P11 | L14: =IF(COUNTA(C14:K14)=0,"",COUNTIF(C14:K14,"Sí")/9) | M14: =IF(L14="","",IF(L14>=0.86,"Totalmente automatizable",IF(L14>=0.71,"Automatizable","Descartar"))) | P14: =IF(OR(N14="",O14=""),"",N14*O14/60)
A15: P12 | L15: =IF(COUNTA(C15:K15)=0,"",COUNTIF(C15:K15,"Sí")/9) | M15: =IF(L15="","",IF(L15>=0.86,"Totalmente automatizable",IF(L15>=0.71,"Automatizable","Descartar"))) | P15: =IF(OR(N15="",O15=""),"",N15*O15/60)
A16: P13 | L16: =IF(COUNTA(C16:K16)=0,"",COUNTIF(C16:K16,"Sí")/9) | M16: =IF(L16="","",IF(L16>=0.86,"Totalmente automatizable",IF(L16>=0.71,"Automatizable","Descartar"))) | P16: =IF(OR(N16="",O16=""),"",N16*O16/60)
A17: P14 | L17: =IF(COUNTA(C17:K17)=0,"",COUNTIF(C17:K17,"Sí")/9) | M17: =IF(L17="","",IF(L17>=0.86,"Totalmente automatizable",IF(L17>=0.71,"Automatizable","Descartar"))) | P17: =IF(OR(N17="",O17=""),"",N17*O17/60)
A18: P15 | L18: =IF(COUNTA(C18:K18)=0,"",COUNTIF(C18:K18,"Sí")/9) | M18: =IF(L18="","",IF(L18>=0.86,"Totalmente automatizable",IF(L18>=0.71,"Automatizable","Descartar"))) | P18: =IF(OR(N18="",O18=""),"",N18*O18/60)
B20: Nota: respuestas y datos operativos son una propuesta inicial de trabajo; validar con el dueño del proceso antes de tomar decisiones.
A21: INSTRUCCIONES: preguntas de viabilidad Q1-Q9 (responda Sí/No por cada proceso, en las columnas C a K de la tabla de arriba)
A22: Las 9 preguntas están redactadas para que 'Sí' sea SIEMPRE la respuesta favorable a la automatización (a mayor número de 'Sí', mayor viabilidad). El 'Puntaje Viabilidad' (columna L) y la 'Clasificación' (columna M) se calculan automáticamente; no los edite.
A23: # | B23: Pregunta completa
A24: Q1 | B24: Las decisiones del proceso se basan en reglas de negocio (no requieren criterio humano)?
A25: Q2 | B25: Los datos que ingresan al proceso siempre tienen un formato/estructura predeterminada?
A26: Q3 | B26: El proceso está estandarizado (siempre se ejecuta de la misma forma)?
A27: Q4 | B27: El proceso está documentado y/o diagramado?
A28: Q5 | B28: La ejecución manual del proceso tiene potencial de generar errores (cansancio, descuido)?
A29: Q6 | B29: El proceso/actividad impacta la experiencia del cliente (interno o externo)?
A30: Q7 | B30: El proceso se inicia por una señal o entrada electrónica (no requiere digitación manual inicial)?
A31: Q8 | B31: El proceso es manual y repetitivo?
A32: Q9 | B32: El proceso es estable (no se esperan cambios en actividades, TI o información en el próximo semestre)?
A34: Clasificación: 86-100% Totalmente automatizable | 71-85% Automatizable | <70% Descartar (misma escala del instrumento original). Todos los procesos de esta pestaña deben ser de la MISMA empresa (ver pestaña '0. Datos Empresa').

Sheet 3. Recomendación Tecnológica
A1: Arbol de Decisión de Tecnologias - evaluación de UN proceso de la empresa
A2: Proceso evaluado (ID): | B2: P01 | C2: Nombre: | D2: =IFERROR(INDEX('2. Priorización Automatización'!$B$4:$B$18,MATCH(B2,'2. Priorización Automatización'!$A$4:$A$18,0)),"") -> Monitoreo de disponibilidad y alertas de switches y puntos de acceso
A3: Empresa: | B3: ='0. Datos Empresa'!$B$4 -> UNIVERSIDAD EAFIT
A5: Resultado por tecnología | D5: Tecnología recomendada: | E5: =IFERROR(INDEX(A7:A14,MATCH(MAX(B7:B14),B7:B14,0)),"") -> Estandarizar + Mejora Continua
A6: Tecnología | B6: Puntaje
A7: Inteligencia Artificial | B7: =SUM(E18:E22) -> 0
A8: RPA | B8: =SUM(E23:E31) -> 0
A9: ETL | B9: =SUM(E32:E34) -> 0
A10: ESB | B10: =SUM(E35:E35) -> 0
A11: Aplicaciones (nueva funcionalidad) | B11: =SUM(E36:E36) -> 0
A12: BPA / BPMS | B12: =SUM(E37:E45) -> 0.5
A13: Estandarizar + Mejora Continua | B13: =SUM(E46:E56) -> 0.94
A14: RPA + OCR | B14: =SUM(E57:E60) -> 0
A16: Preguntas (responda Sí/No para el proceso seleccionado arriba)
A17: Tecnología | B17: Pregunta | C17: Peso | D17: Respuesta | E17: Puntaje
A18: Inteligencia Artificial | B18: Existen datos históricos que permitan realizar pronósticos? | C18: 0.2 | D18: No | E18: =IF(D18="",0,IF(D18="Sí",C18,0)) -> 0
A19: Inteligencia Artificial | B19: Se identifica que existen preguntas frecuentes? | C19: 0.2 | D19: No | E19: =IF(D19="",0,IF(D19="Sí",C19,0)) -> 0
A20: Inteligencia Artificial | B20: Existen variables relacionables para establecer un modelo de decisión? | C20: 0.2 | D20: No | E20: =IF(D20="",0,IF(D20="Sí",C20,0)) -> 0
A21: Inteligencia Artificial | B21: Se requiere identificar patrones? | C21: 0.2 | D21: No | E21: =IF(D21="",0,IF(D21="Sí",C21,0)) -> 0
A22: Inteligencia Artificial | B22: El proceso requiere extraer o interpretar información de un texto? | C22: 0.2 | D22: No | E22: =IF(D22="",0,IF(D22="Sí",C22,0)) -> 0
A23: RPA | B23: Se procesan altos volúmenes de transacciones por medio de interfaces de usuario? | C23: 0.1111 | D23: No | E23: =IF(D23="",0,IF(D23="Sí",C23,0)) -> 0
A24: RPA | B24: El proceso es manual y repetitivo? | C24: 0.1111 | D24: No | E24: =IF(D24="",0,IF(D24="Sí",C24,0)) -> 0
A25: RPA | B25: Las transacciones toman un tiempo considerable en ser atendidas? | C25: 0.1111 | D25: No | E25: =IF(D25="",0,IF(D25="Sí",C25,0)) -> 0
A26: RPA | B26: Los datos de entrada del proceso son estructurados? | C26: 0.1111 | D26: No | E26: =IF(D26="",0,IF(D26="Sí",C26,0)) -> 0
A27: RPA | B27: El proceso tiene una baja tasa de excepciones? | C27: 0.1111 | D27: No | E27: =IF(D27="",0,IF(D27="Sí",C27,0)) -> 0
A28: RPA | B28: El proceso está basado en reglas de negocio? | C28: 0.1111 | D28: No | E28: =IF(D28="",0,IF(D28="Sí",C28,0)) -> 0
A29: RPA | B29: Las entradas de información se encuentran estandarizadas? | C29: 0.1111 | D29: No | E29: =IF(D29="",0,IF(D29="Sí",C29,0)) -> 0
... A60: RPA + OCR | B60: Se requiere custodia electrónica de documentos? | C60: 0.2 | D60: No | E60: =IF(D60="",0,IF(D60="Sí",C60,0)) -> 0
A61: Para evaluar otro proceso de la MISMA empresa: duplique esta pestaña (clic derecho > Mover o copiar > Crear una copia) y cambie el 'Proceso evaluado' de la copia. Registre la tecnología recomendada resultante en la pestaña '4. Dashboard'.

Sheet 3. Rec. Tec. P02
A1: Arbol de Decisión de Tecnologias - evaluación de UN proceso de la empresa
A2: Proceso evaluado (ID): | B2: P02 | C2: Nombre: | D2: =IFERROR(INDEX('2. Priorización Automatización'!$B$4:$B$18,MATCH(B2,'2. Priorización Automatización'!$A$4:$A$18,0)),"") -> Monitoreo de disponibilidad y alertas de switches y puntos de acceso
A3: Empresa: | B3: ='0. Datos Empresa'!$B$4 -> UNIVERSIDAD EAFIT
A5: Resultado por tecnología | D5: Tecnología recomendada: | E5: =IFERROR(INDEX(A7:A14,MATCH(MAX(B7:B14),B7:B14,0)),"") -> Estandarizar + Mejora Continua
A6: Tecnología | B6: Puntaje
A7: Inteligencia Artificial | B7: =SUM(E18:E22) -> 0
A8: RPA | B8: =SUM(E23:E31) -> 0
A9: ETL | B9: =SUM(E32:E34) -> 0
A10: ESB | B10: =SUM(E35:E35) -> 0
A11: Aplicaciones (nueva funcionalidad) | B11: =SUM(E36:E36) -> 0
A12: BPA / BPMS | B12: =SUM(E37:E45) -> 0.5
A13: Estandarizar + Mejora Continua | B13: =SUM(E46:E56) -> 0.94
A14: RPA + OCR | B14: =SUM(E57:E60) -> 0
A16: Preguntas (responda Sí/No para el proceso seleccionado arriba)
A17: Tecnología | B17: Pregunta | C17: Peso | D17: Respuesta | E17: Puntaje
A18: Inteligencia Artificial | B18: Existen datos históricos que permitan realizar pronósticos? | C18: 0.2 | D18: No | E18: =IF(D18="",0,IF(D18="Sí",C18,0)) -> 0
A19: Inteligencia Artificial | B19: Se identifica que existen preguntas frecuentes? | C19: 0.2 | D19: No | E19: =IF(D19="",0,IF(D19="Sí",C19,0)) -> 0
A20: Inteligencia Artificial | B20: Existen variables relacionables para establecer un modelo de decisión? | C20: 0.2 | D20: No | E20: =IF(D20="",0,IF(D20="Sí",C20,0)) -> 0
A21: Inteligencia Artificial | B21: Se requiere identificar patrones? | C21: 0.2 | D21: No | E21: =IF(D21="",0,IF(D21="Sí",C21,0)) -> 0
A22: Inteligencia Artificial | B22: El proceso requiere extraer o interpretar información de un texto? | C22: 0.2 | D22: No | E22: =IF(D22="",0,IF(D22="Sí",C22,0)) -> 0
A23: RPA | B23: Se procesan altos volúmenes de transacciones por medio de interfaces de usuario? | C23: 0.1111 | D23: Sí | E23: =IF(D23="",0,IF(D23="Sí",C23,0)) -> 0
A24: RPA | B24: El proceso es manual y repetitivo? | C24: 0.1111 | D24: Sí | E24: =IF(D24="",0,IF(D24="Sí",C24,0)) -> 0
A25: RPA | B25: Las transacciones toman un tiempo considerable en ser atendidas? | C25: 0.1111 | D25: Sí | E25: =IF(D25="",0,IF(D25="Sí",C25,0)) -> 0
A26: RPA | B26: Los datos de entrada del proceso son estructurados? | C26: 0.1111 | D26: Sí | E26: =IF(D26="",0,IF(D26="Sí",C26,0)) -> 0
A27: RPA | B27: El proceso tiene una baja tasa de excepciones? | C27: 0.1111 | D27: Sí | E27: =IF(D27="",0,IF(D27="Sí",C27,0)) -> 0
A28: RPA | B28: El proceso está basado en reglas de negocio? | C28: 0.1111 | D28: Sí | E28: =IF(D28="",0,IF(D28="Sí",C28,0)) -> 0
A29: RPA | B29: Las entradas de información se encuentran estandarizadas? | C29: 0.1111 | D29: Sí | E29: =IF(D29="",0,IF(D29="Sí",C29,0)) -> 0
... A60: RPA + OCR | B60: Se requiere custodia electrónica de documentos? | C60: 0.2 | D60: No | E60: =IF(D60="",0,IF(D60="Sí",C60,0)) -> 0
A61: Para evaluar otro proceso de la MISMA empresa: duplique esta pestaña (clic derecho > Mover o copiar > Crear una copia) y cambie el 'Proceso evaluado' de la copia. Registre la tecnología recomendada resultante en la pestaña '4. Dashboard'.

Sheet 3. Rec. Tec. P08
A1: Arbol de Decisión de Tecnologias - evaluación de UN proceso de la empresa
A2: Proceso evaluado (ID): | B2: P08 | C2: Nombre: | D2: =IFERROR(INDEX('2. Priorización Automatización'!$B$4:$B$18,MATCH(B2,'2. Priorización Automatización'!$A$4:$A$18,0)),"") -> Monitoreo de disponibilidad y alertas de switches y puntos de acceso
A3: Empresa: | B3: ='0. Datos Empresa'!$B$4 -> UNIVERSIDAD EAFIT
A5: Resultado por tecnología | D5: Tecnología recomendada: | E5: =IFERROR(INDEX(A7:A14,MATCH(MAX(B7:B14),B7:B14,0)),"") -> Estandarizar + Mejora Continua
A6: Tecnología | B6: Puntaje
A7: Inteligencia Artificial | B7: =SUM(E18:E22) -> 0
A8: RPA | B8: =SUM(E23:E31) -> 0
A9: ETL | B9: =SUM(E32:E34) -> 0
A10: ESB | B10: =SUM(E35:E35) -> 0
A11: Aplicaciones (nueva funcionalidad) | B11: =SUM(E36:E36) -> 0
A12: BPA / BPMS | B12: =SUM(E37:E45) -> 0.5
A13: Estandarizar + Mejora Continua | B13: =SUM(E46:E56) -> 0.94
A14: RPA + OCR | B14: =SUM(E57:E60) -> 0
A16: Preguntas (responda Sí/No para el proceso seleccionado arriba)
A17: Tecnología | B17: Pregunta | C17: Peso | D17: Respuesta | E17: Puntaje
A18: Inteligencia Artificial | B18: Existen datos históricos que permitan realizar pronósticos? | C18: 0.2 | D18: Sí | E18: =IF(D18="",0,IF(D18="Sí",C18,0)) -> 0
A19: Inteligencia Artificial | B19: Se identifica que existen preguntas frecuentes? | C19: 0.2 | D19: Sí | E19: =IF(D19="",0,IF(D19="Sí",C19,0)) -> 0
A20: Inteligencia Artificial | B20: Existen variables relacionables para establecer un modelo de decisión? | C20: 0.2 | D20: Sí | E20: =IF(D20="",0,IF(D20="Sí",C20,0)) -> 0
A21: Inteligencia Artificial | B21: Se requiere identificar patrones? | C21: 0.2 | D21: Sí | E21: =IF(D21="",0,IF(D21="Sí",C21,0)) -> 0
A22: Inteligencia Artificial | B22: El proceso requiere extraer o interpretar información de un texto? | C22: 0.2 | D22: Sí | E22: =IF(D22="",0,IF(D22="Sí",C22,0)) -> 0
A23: RPA | B23: Se procesan altos volúmenes de transacciones por medio de interfaces de usuario? | C23: 0.1111 | D23: Sí | E23: =IF(D23="",0,IF(D23="Sí",C23,0)) -> 0
A24: RPA | B24: El proceso es manual y repetitivo? | C24: 0.1111 | D24: Sí | E24: =IF(D24="",0,IF(D24="Sí",C24,0)) -> 0
A25: RPA | B25: Las transacciones toman un tiempo considerable en ser atendidas? | C25: 0.1111 | D25: Sí | E25: =IF(D25="",0,IF(D25="Sí",C25,0)) -> 0
A26: RPA | B26: Los datos de entrada del proceso son estructurados? | C26: 0.1111 | D26: No | E26: =IF(D26="",0,IF(D26="Sí",C26,0)) -> 0
A27: RPA | B27: El proceso tiene una baja tasa de excepciones? | C27: 0.1111 | D27: No | E27: =IF(D27="",0,IF(D27="Sí",C27,0)) -> 0
A28: RPA | B28: El proceso está basado en reglas de negocio? | C28: 0.1111 | D28: No | E28: =IF(D28="",0,IF(D28="Sí",C28,0)) -> 0
A29: RPA | B29: Las entradas de información se encuentran estandarizadas? | C29: 0.1111 | D29: No | E29: =IF(D29="",0,IF(D29="Sí",C29,0)) -> 0
... A60: RPA + OCR | B60: Se requiere custodia electrónica de documentos? | C60: 0.2 | D60: No | E60: =IF(D60="",0,IF(D60="Sí",C60,0)) -> 0
A61: Para evaluar otro proceso de la MISMA empresa: duplique esta pestaña (clic derecho > Mover o copiar > Crear una copia) y cambie el 'Proceso evaluado' de la copia. Registre la tecnología recomendada resultante en la pestaña '4. Dashboard'.

Sheet 4. Dashboard
A1: Dashboard de Automatización de Procesos
A2: Empresa: | B2: ='0. Datos Empresa'!$B$4 -> UNIVERSIDAD EAFIT
A4: Procesos registrados | F4: Procesos evaluados (con puntaje) | K4: Costo externo total ($/mes)
A5: =COUNTA('2. Priorización Automatización'!$B$4:$B$18) -> 8 | F5: =COUNT('2. Priorización Automatización'!$L$4:$L$18) -> 8 | K5: =SUM('2. Priorización Automatización'!$R$4:$R$18) -> 0
A7: % Totalmente automatizable | F7: % Automatizable | K7: % Descartar
A8: =IFERROR(COUNTIF('2. Priorización Automatización'!$M$4:$M$18,"Totalmente automatizable")/COUNT('2. Priorización Automatización'!$L$4:$L$18),0) -> 0.875 | F8: =IFERROR(COUNTIF('2. Priorización Automatización'!$M$4:$M$18,"Automatizable")/COUNT('2. Priorización Automatización'!$L$4:$L$18),0) -> 0.125 | K8: =IFERROR(COUNTIF('2. Priorización Automatización'!$M$4:$M$18,"Descartar")/COUNT('2. Priorización Automatización'!$L$4:$L$18),0) -> 0
A10: Horas/mes con potencial de automatizarse | F10: Personas impactadas (procesos automatizables) | K10: Puntaje viabilidad promedio
A11: =SUMIFS('2. Priorización Automatización'!$P$4:$P$18,'2. Priorización Automatización'!$M$4:$M$18,"Totalmente automatizable")+SUMIFS('2. Priorización Automatización'!$P$4:$P$18,'2. Priorización Automatización'!$M$4:$M$18,"Automatizable") -> 240.33333 | F11: =SUMIFS('2. Priorización Automatización'!$Q$4:$Q$18,'2. Priorización Automatización'!$M$4:$M$18,"Totalmente automatizable")+SUMIFS('2. Priorización Automatización'!$Q$4:$Q$18,'2. Priorización Automatización'!$M$4:$M$18,"Automatizable") -> 19 | K11: =IFERROR(AVERAGE('2. Priorización Automatización'!$L$4:$L$18),0) -> 0.93055556
A13: Distribución por clasificación | F13: Tecnología recomendada por proceso (registro manual)
A14: Clasificación | B14: No. procesos | F14: Transcriba aquí la 'Tecnología recomendada' que arroje cada copia de la pestaña '3. Recomendación Tecnológica' (una copia por proceso evaluado).
A15: Totalmente automatizable | B15: =COUNTIF('2. Priorización Automatización'!$M$4:$M$18,"Totalmente automatizable") -> 7
A16: Automatizable | B16: =COUNTIF('2. Priorización Automatización'!$M$4:$M$18,"Automatizable") -> 1 | F16: ID Proceso | G16: Nombre del proceso | H16: Tecnología recomendada | J16: Tecnología | K16: No. procesos
A17: Descartar | B17: =COUNTIF('2. Priorización Automatización'!$M$4:$M$18,"Descartar") -> 0 | F17: P01 | G17: =IFERROR(INDEX('2. Priorización Automatización'!$B$4:$B$18,MATCH(F17,'2. Priorización Automatización'!$A$4:$A$18,0)),"") -> Monitoreo de disponibilidad y alertas de switches y puntos de acceso | H17: Estandarizar + Mejora Continua | J17: Inteligencia Artificial | K17: =COUNTIF($H$17:$H$31,"Inteligencia Artificial") -> 0
F18: P02 | G18: =IFERROR(INDEX('2. Priorización Automatización'!$B$4:$B$18,MATCH(F18,'2. Priorización Automatización'!$A$4:$A$18,0)),"") -> Generación periódica de reportes de desempeño de red | H18: RPA | J18: RPA | K18: =COUNTIF($H$17:$H$31,"RPA") -> 1
F19: P03 | G19: =IFERROR(INDEX('2. Priorización Automatización'!$B$4:$B$18,MATCH(F19,'2. Priorización Automatización'!$A$4:$A$18,0)),"") -> Registro, clasificación y seguimiento de incidentes de conectividad | H19: BPA / BPMS | J19: ETL | K19: =COUNTIF($H$17:$H$31,"ETL") -> 0
F20: P04 | G20: =IFERROR(INDEX('2. Priorización Automatización'!$B$4:$B$18,MATCH(F20,'2. Priorización Automatización'!$A$4:$A$18,0)),"") -> Inventario y actualización de información de switches y AP | H20: Estandarizar + Mejora Continua | J20: ESB | K20: =COUNTIF($H$17:$H$31,"ESB") -> 0
F21: P05 | G21: =IFERROR(INDEX('2. Priorización Automatización'!$B$4:$B$18,MATCH(F21,'2. Priorización Automatización'!$A$4:$A$18,0)),"") -> Revisión y consolidación de logs de infraestructura | H21: Estandarizar + Mejora Continua | J21: Aplicaciones (nueva funcionalidad) | K21: =COUNTIF($H$17:$H$31,"Aplicaciones (nueva funcionalidad)") -> 0
F22: P06 | G22: =IFERROR(INDEX('2. Priorización Automatización'!$B$4:$B$18,MATCH(F22,'2. Priorización Automatización'!$A$4:$A$18,0)),"") -> Programación y seguimiento de actualizaciones de firmware | H22: BPA / BPMS | J22: BPA / BPMS | K22: =COUNTIF($H$17:$H$31,"BPA / BPMS") -> 3
F23: P07 | G23: =IFERROR(INDEX('2. Priorización Automatización'!$B$4:$B$18,MATCH(F23,'2. Priorización Automatización'!$A$4:$A$18,0)),"") -> Gestión de solicitudes de habilitación de puntos de red y VLAN | H23: BPA / BPMS | J23: Estandarizar + Mejora Continua | K23: =COUNTIF($H$17:$H$31,"Estandarizar + Mejora Continua") -> 4
F24: P08 | G24: =IFERROR(INDEX('2. Priorización Automatización'!$B$4:$B$18,MATCH(F24,'2. Priorización Automatización'!$A$4:$A$18,0)),"") -> Seguimiento de ocupación estimada de aulas mediante sensores ESP32 | H24: Estandarizar + Mejora Continua | J24: RPA + OCR | K24: =COUNTIF($H$17:$H$31,"RPA + OCR") -> 0
G25: =IFERROR(INDEX('2. Priorización Automatización'!$B$4:$B$18,MATCH(F25,'2. Priorización Automatización'!$A$4:$A$18,0)),"")
G26: =IFERROR(INDEX('2. Priorización Automatización'!$B$4:$B$18,MATCH(F26,'2. Priorización Automatización'!$A$4:$A$18,0)),"")
G27: =IFERROR(INDEX('2. Priorización Automatización'!$B$4:$B$18,MATCH(F27,'2. Priorización Automatización'!$A$4:$A$18,0)),"")
G28: =IFERROR(INDEX('2. Priorización Automatización'!$B$4:$B$18,MATCH(F28,'2. Priorización Automatización'!$A$4:$A$18,0)),"")
G29: =IFERROR(INDEX('2. Priorización Automatización'!$B$4:$B$18,MATCH(F29,'2. Priorización Automatización'!$A$4:$A$18,0)),"")
G30: =IFERROR(INDEX('2. Priorización Automatización'!$B$4:$B$18,MATCH(F30,'2. Priorización Automatización'!$A$4:$A$18,0)),"")
G31: =IFERROR(INDEX('2. Priorización Automatización'!$B$4:$B$18,MATCH(F31,'2. Priorización Automatización'!$A$4:$A$18,0)),"")
A51: Portafolio de procesos (Viabilidad x Horas/mes x Personas)
A52: Cada burbuja es un proceso de la pestaña '2. Priorización Automatización': eje X = puntaje de viabilidad, eje Y = horas/mes dedicadas, tamano = personas involucradas.
A54: Viabilidad | B54: Horas/mes | C54: Personas
A55: =IFERROR(VALUE('2. Priorización Automatización'!L4),0) -> 1 | B55: =IFERROR(VALUE('2. Priorización Automatización'!P4),0) -> 60 | C55: =IFERROR(VALUE('2. Priorización Automatización'!Q4),0) -> 3
A56: =IFERROR(VALUE('2. Priorización Automatización'!L5),0) -> 1 | B56: =IFERROR(VALUE('2. Priorización Automatización'!P5),0) -> 40 | C56: =IFERROR(VALUE('2. Priorización Automatización'!Q5),0) -> 2
A57: =IFERROR(VALUE('2. Priorización Automatización'!L6),0) -> 0.88888889 | B57: =IFERROR(VALUE('2. Priorización Automatización'!P6),0) -> 36 | C57: =IFERROR(VALUE('2. Priorización Automatización'!Q6),0) -> 4
A58: =IFERROR(VALUE('2. Priorización Automatización'!L7),0) -> 0.88888889 | B58: =IFERROR(VALUE('2. Priorización Automatización'!P7),0) -> 13.333333 | C58: =IFERROR(VALUE('2. Priorización Automatización'!Q7),0) -> 2
A59: =IFERROR(VALUE('2. Priorización Automatización'!L8),0) -> 1 | B59: =IFERROR(VALUE('2. Priorización Automatización'!P8),0) -> 20 | C59: =IFERROR(VALUE('2. Priorización Automatización'!Q8),0) -> 2
A60: =IFERROR(VALUE('2. Priorización Automatización'!L9),0) -> 0.77777778 | B60: =IFERROR(VALUE('2. Priorización Automatización'!P9),0) -> 6 | C60: =IFERROR(VALUE('2. Priorización Automatización'!Q9),0) -> 2
A61: =IFERROR(VALUE('2. Priorización Automatización'!L10),0) -> 0.88888889 | B61: =IFERROR(VALUE('2. Priorización Automatización'!P10),0) -> 20 | C61: =IFERROR(VALUE('2. Priorización Automatización'!Q10),0) -> 3
A62: =IFERROR(VALUE('2. Priorización Automatización'!L11),0) -> 1 | B62: =IFERROR(VALUE('2. Priorización Automatización'!P11),0) -> 45 | C62: =IFERROR(VALUE('2. Priorización Automatización'!Q11),0) -> 1
A63: =IFERROR(VALUE('2. Priorización Automatización'!L12),0) -> 0 | B63: =IFERROR(VALUE('2. Priorización Automatización'!P12),0) -> 0 | C63: =IFERROR(VALUE('2. Priorización Automatización'!Q12),0) -> 0
A64: =IFERROR(VALUE('2. Priorización Automatización'!L13),0) -> 0 | B64: =IFERROR(VALUE('2. Priorización Automatización'!P13),0) -> 0 | C64: =IFERROR(VALUE('2. Priorización Automatización'!Q13),0) -> 0
...
